Workbook
Name TaskStatusList: Lists!$A$2:$A$8
Name WeekStatusList: Lists!$B$2:$B$6
Name FailureTagList: Lists!$C$2:$C$7
Name VirtualStatusList: Lists!$D$2:$D$5

Sheet Dashboard
A1: ICPC 2026-2027 TRAINING CONTROL BOARD
A3: From 21/06/2026 to APAC preparation cutoff 28/02/2027 | Default load: 12-15h/week
A5: MILESTONE | B5: DATE | C5: DAYS LEFT | D5: TRAINING TARGET | E5: STATUS | G5: KPI | H5: VALUE
A6: ICPC Southern | B6: 46312 | C6: =MAX(0,B6-TODAY()) -> 118 | D6: 5-7 solves; no easy miss | E6: Upcoming | G6: Task AC | H6: =COUNTIF('Task Bank'!$F:$F,"AC") -> 0
A7: ICPC National | B7: 46334 | C7: =MAX(0,B7-TODAY()) -> 140 | D7: Owner roles + stable B/C | E7: Upcoming | G7: Unique task entries | H7: =COUNTA('Task Bank'!$A:$A)-1-COUNTIF('Task Bank'!$F:$F,"Reference") -> 176
A8: Asia Regional Da Nang | B8: 46366 | C8: =MAX(0,B8-TODAY()) -> 172 | D8: 3 virtuals at 5+ solves | E8: Upcoming | G8: Retry due | H8: =COUNTIFS('Task Bank'!$F:$F,"Retry",'Task Bank'!$M:$M,"<="&TODAY()) -> 0
A9: APAC Tokyo | B9: 46447 | C9: =MAX(0,B9-TODAY()) -> 253 | D9: 5-7 solves on APAC old sets | E9: Month placeholder | G9: Virtuals done | H9: =COUNTIF('Virtual Log'!$F:$F,"Done") -> 0
G10: Average solved | H10: =IFERROR(AVERAGEIF('Virtual Log'!$F:$F,"Done",'Virtual Log'!$G:$G),0) -> 0
G11: Actual hours | H11: =SUM('Weekly Plan'!$K:$K) -> 0
A13: TOPIC PROGRESS | B13: PRIORITY | C13: AC / TASKS | D13: PROGRESS | F13: HOW TO USE THIS FILE
A14: ='Topic Gates'!A2 -> 00 - Implementation, Greedy, Search | B14: ='Topic Gates'!B2 -> P0 | C14: ='Topic Gates'!H2 -> 0 / 16 | D14: ='Topic Gates'!I2 -> 0 | F14: 1. Open Weekly Plan and follow only the current week. 2. In Task Bank, update Status, AC date, WA and notes. 3. Log every 5-hour contest in Virtual Log. 4. Retry failed tasks after 7 and 21 days. 5. Do not solve all 184 entries; pass Topic Gates. 6. APAC date is a March placeholder until exact date is published.
A15: ='Topic Gates'!A3 -> 01 - Graph and Modeling | B15: ='Topic Gates'!B3 -> P0/P1 | C15: ='Topic Gates'!H3 -> 0 / 24 | D15: ='Topic Gates'!I3 -> 0
A16: ='Topic Gates'!A4 -> 02 - Data Structures | B16: ='Topic Gates'!B4 -> P0/P2 | C16: ='Topic Gates'!H4 -> 0 / 20 | D16: ='Topic Gates'!I4 -> 0
A17: ='Topic Gates'!A5 -> 03 - Tree | B17: ='Topic Gates'!B5 -> P0/P1 | C17: ='Topic Gates'!H5 -> 0 / 20 | D17: ='Topic Gates'!I5 -> 0
A18: ='Topic Gates'!A6 -> 04 - Advanced DP | B18: ='Topic Gates'!B6 -> P0/P1 | C18: ='Topic Gates'!H6 -> 0 / 21 | D18: ='Topic Gates'!I6 -> 0
A19: ='Topic Gates'!A7 -> 05 - Math and Counting | B19: ='Topic Gates'!B7 -> P0/P2 | C19: ='Topic Gates'!H7 -> 0 / 21 | D19: ='Topic Gates'!I7 -> 0
A20: ='Topic Gates'!A8 -> 06 - Strings | B20: ='Topic Gates'!B8 -> P0/P1 | C20: ='Topic Gates'!H8 -> 0 / 19 | D20: ='Topic Gates'!I8 -> 0
A21: ='Topic Gates'!A9 -> 07 - Geometry | B21: ='Topic Gates'!B9 -> P1 | C21: ='Topic Gates'!H9 -> 0 / 18 | D21: ='Topic Gates'!I9 -> 0 | F21: CURRENT DEFINITION OF READY
A22: ='Topic Gates'!A10 -> 08 - Proof, Constructive, Game | B22: ='Topic Gates'!B10 -> P1 | C22: ='Topic Gates'!H10 -> 0 / 17 | D22: ='Topic Gates'!I10 -> 0 | F22: Regional: pass topic gates, then score 5+ on three consecutive Regional virtuals without missing easy tasks because of primitive gaps. APAC: owner coverage, two coding streams, and trend toward 5-7 solves on APAC old sets.
A27: Start here: Weekly Plan -> Task Bank -> Virtual Log -> Topic Gates

Sheet Weekly Plan
A1: Week | B1: From | C1: To | D1: Phase | E1: Planned hrs | F1: Focus | G1: Assigned tasks / rule | H1: Virtual / Contest | I1: Output / Gate | J1: Status | K1: Actual hrs | L1: Task completion | M1: Notes
A2: 1 | B2: 46195 | C2: 46201 | D2: Phase 0 - Baseline | E2: 13 | F2: Implementation + baseline | G2: 00 A: Apartments; Factory Machines; Max Subarray II; Sum of Four Values | H2: Southern 2023 virtual | I2: Record score, WA, first AC; freeze basic C++ workflow | J2: Not started | L2: =IF(COUNTIF('Task Bank'!$H:$H,A2)=0,"",COUNTIFS('Task Bank'!$H:$H,A2,'Task Bank'!$F:$F,"AC")/COUNTIF('Task Bank'!$H:$H,A2)) -> 0
A3: 2 | B3: 46202 | C3: 46208 | D3: Phase 1 - Foundation | E3: 13 | F3: Greedy, binary search, two pointers, MITM | G3: 00 B: Movie Festival II; Array Division; Collecting Numbers II; MITM; Traffic Lights | H3: Southern 2024 virtual | I3: 3 easy problems inside 90 minutes | J3: Not started | L3: =IF(COUNTIF('Task Bank'!$H:$H,A3)=0,"",COUNTIFS('Task Bank'!$H:$H,A3,'Task Bank'!$F:$F,"AC")/COUNTIF('Task Bank'!$H:$H,A3)) -> 0
A4: 3 | B4: 46209 | C4: 46215 | D4: Phase 1 - Foundation | E4: 13 | F4: Graph shortest path, SCC, MST, low-link | G4: Graph A: Flight Discount; Investigation; Coin Collector; Road Reparation; Necessary Roads/Cities | H4: Graph mashup 5h | I4: Dijkstra/SCC/low-link written without template copy | J4: Not started | L4: =IF(COUNTIF('Task Bank'!$H:$H,A4)=0,"",COUNTIFS('Task Bank'!$H:$H,A4,'Task Bank'!$F:$F,"AC")/COUNTIF('Task Bank'!$H:$H,A4)) -> 0
A5: 4 | B5: 46216 | C5: 46222 | D5: Phase 1 - Foundation | E5: 13 | F5: Fenwick, lazy segment tree, sparse table | G5: DS A: range update/sum; salary; RMQ; GSS3; ORDERSET | H5: DS mashup 5h | I5: Lazy assign/add stress passes small brute | J5: Not started | L5: =IF(COUNTIF('Task Bank'!$H:$H,A5)=0,"",COUNTIFS('Task Bank'!$H:$H,A5,'Task Bank'!$F:$F,"AC")/COUNTIF('Task Bank'!$H:$H,A5)) -> 0
A6: 5 | B6: 46223 | C6: 46229 | D6: Phase 1 - Foundation | E6: 13 | F6: Tree LCA, Euler, difference, rerooting | G6: Tree A: Company Queries II; Counting Paths; Path Queries; Tree Distances II | H6: Tree mashup 5h | I6: LCA + Euler + rerooting from scratch | J6: Not started | L6: =IF(COUNTIF('Task Bank'!$H:$H,A6)=0,"",COUNTIFS('Task Bank'!$H:$H,A6,'Task Bank'!$F:$F,"AC")/COUNTIF('Task Bank'!$H:$H,A6)) -> 0
A7: 6 | B7: 46230 | C7: 46236 | D7: Phase 1 - Foundation | E7: 13 | F7: DP interval, bitmask, profile, digit | G7: DP A: Projects; Removal Game; Elevator Rides; Counting Tilings; Counting Numbers | H7: DP mashup 5h | I7: Write recurrence and complexity before coding | J7: Not started | L7: =IF(COUNTIF('Task Bank'!$H:$H,A7)=0,"",COUNTIFS('Task Bank'!$H:$H,A7,'Task Bank'!$F:$F,"AC")/COUNTIF('Task Bank'!$H:$H,A7)) -> 0
A8: 7 | B8: 46237 | C8: 46243 | D8: Phase 1 - Foundation | E8: 14 | F8: Math core + string primitives | G8: Math A + KMP/Z: divisors; nCk; inclusion-exclusion; String Matching; Borders | H8: Southern 2025 virtual | I8: No primitive gap on easy/medium tasks | J8: Not started | L8: =IF(COUNTIF('Task Bank'!$H:$H,A8)=0,"",COUNTIFS('Task Bank'!$H:$H,A8,'Task Bank'!$F:$F,"AC")/COUNTIF('Task Bank'!$H:$H,A8)) -> 0
A9: 8 | B9: 46244 | C9: 46250 | D9: Phase 2 - Regional core | E9: 14 | F9: Flow, matching, min-cut, 2-SAT | G9: Download Speed; Police Chase; School Dance; Distinct Routes; Giant Pizza | H9: National 2021 virtual | I9: One AC flow and one min-cut reconstruction | J9: Not started | L9: =IF(COUNTIF('Task Bank'!$H:$H,A9)=0,"",COUNTIFS('Task Bank'!$H:$H,A9,'Task Bank'!$F:$F,"AC")/COUNTIF('Task Bank'!$H:$H,A9)) -> 0
A10: 9 | B10: 46251 | C10: 46257 | D10: Phase 2 - Regional core | E10: 14 | F10: HLD, DSU on tree, path counting | G10: Path Queries II; Fools and Roads; QTREE; Fixed-Length Paths I; Lomsat gelral | H10: Tree/DS team mashup | I10: HLD from scratch; one owner advanced tree | J10: Not started | L10: =IF(COUNTIF('Task Bank'!$H:$H,A10)=0,"",COUNTIFS('Task Bank'!$H:$H,A10,'Task Bank'!$F:$F,"AC")/COUNTIF('Task Bank'!$H:$H,A10)) -> 0
A11: 10 | B11: 46258 | C11: 46264 | D11: Phase 2 - Regional core | E11: 14 | F11: Aho-Corasick, suffix array/LCP | G11: Word Combinations; Finding/Counting Patterns; Pattern Positions; Repeating Substring | H11: String mashup 5h | I11: One Aho AC and one suffix-array AC | J11: Not started | L11: =IF(COUNTIF('Task Bank'!$H:$H,A11)=0,"",COUNTIFS('Task Bank'!$H:$H,A11,'Task Bank'!$F:$F,"AC")/COUNTIF('Task Bank'!$H:$H,A11)) -> 0
A12: 11 | B12: 46265 | C12: 46271 | D12: Phase 2 - Regional core | E12: 14 | F12: Robust geometry + sweep line | G12: Point/segment/polygon; Convex Hull; Intersection Points | H12: Geometry mashup 5h | I12: Integer primitives survive edge-case suite | J12: Not started | L12: =IF(COUNTIF('Task Bank'!$H:$H,A12)=0,"",COUNTIFS('Task Bank'!$H:$H,A12,'Task Bank'!$F:$F,"AC")/COUNTIF('Task Bank'!$H:$H,A12)) -> 0
A13: 12 | B13: 46272 | C13: 46278 | D13: Phase 2 - Regional core | E13: 14 | F13: DP optimization | G13: Intervals; Frog 3; Houses and Schools; Knuth Division; Sushi | H13: National 2022 virtual | I13: Explain condition for CHT/D&C/Knuth | J13: Not started | L13: =IF(COUNTIF('Task Bank'!$H:$H,A13)=0,"",COUNTIFS('Task Bank'!$H:$H,A13,'Task Bank'!$F:$F,"AC")/COUNTIF('Task Bank'!$H:$H,A13)) -> 0
... A37: 36 | B37: 46440 | C37: 46446 | D37: Phase 6 - APAC taper | E37: 10 | F37: Retry + notebook freeze | G37: Only failed medium tasks and template stress | H37: One light replay | I37: Ready by 28/02; APAC date still TBD in March | J37: Not started | L37: =IF(COUNTIF('Task Bank'!$H:$H,A37)=0,"",COUNTIFS('Task Bank'!$H:$H,A37,'Task Bank'!$F:$F,"AC")/COUNTIF('Task Bank'!$H:$H,A37))

Sheet Task Bank
A1: ID | B1: Topic | C1: Tier | D1: Task | E1: Submit | F1: Status | G1: Owner folder | H1: Planned week | I1: Start date | J1: AC date | K1: Minutes | L1: WA | M1: Retry +7 | N1: Retry +21 | O1: Key / Focus | P1: Notes | Q1: Source file
A2: 1 | B2: 00 - Implementation, Greedy, Search | C2: A - Foundation | D2: Apartments | E2: Submit | F2: Not started | G2: 00_implementation_greedy_search | H2: 1 | M2: =IF(J2="","",J2+7) | N2: =IF(J2="","",J2+21) | O2: sorting + two pointers. | Q2: regional\Tasks\00_implementation_greedy_search\README.md
A3: 2 | B3: 00 - Implementation, Greedy, Search | C3: A - Foundation | D3: Factory Machines | E3: Submit | F3: Not started | G3: 00_implementation_greedy_search | H3: 1 | M3: =IF(J3="","",J3+7) | N3: =IF(J3="","",J3+21) | O3: binary search answer, overflow-safe predicate. | Q3: regional\Tasks\00_implementation_greedy_search\README.md
A4: 3 | B4: 00 - Implementation, Greedy, Search | C4: A - Foundation | D4: Maximum Subarray Sum II | E4: Submit | F4: Not started | G4: 00_implementation_greedy_search | H4: 1 | M4: =IF(J4="","",J4+7) | N4: =IF(J4="","",J4+21) | O4: prefix sums + sliding ordered minimum. | Q4: regional\Tasks\00_implementation_greedy_search\README.md
A5: 4 | B5: 00 - Implementation, Greedy, Search | C5: A - Foundation | D5: Sum of Four Values | E5: Submit | F5: Not started | G5: 00_implementation_greedy_search | H5: 1 | M5: =IF(J5="","",J5+7) | N5: =IF(J5="","",J5+21) | O5: pair sums, ordering indices, complexity accounting. | Q5: regional\Tasks\00_implementation_greedy_search\README.md
A6: 5 | B6: 00 - Implementation, Greedy, Search | C6: B - Regional core | D6: Movie Festival II | E6: Submit | F6: Not started | G6: 00_implementation_greedy_search | H6: 2 | M6: =IF(J6="","",J6+7) | N6: =IF(J6="","",J6+21) | O6: greedy + multiset; prove latest compatible resource. | Q6: regional\Tasks\00_implementation_greedy_search\README.md
A7: 6 | B7: 00 - Implementation, Greedy, Search | C7: B - Regional core | D7: Array Division | E7: Submit | F7: Not started | G7: 00_implementation_greedy_search | H7: 2 | M7: =IF(J7="","",J7+7) | N7: =IF(J7="","",J7+21) | O7: binary search + greedy feasibility. | Q7: regional\Tasks\00_implementation_greedy_search\README.md
A8: 7 | B8: 00 - Implementation, Greedy, Search | C8: B - Regional core | D8: Collecting Numbers II | E8: Submit | F8: Not started | G8: 00_implementation_greedy_search | H8: 2 | M8: =IF(J8="","",J8+7) | N8: =IF(J8="","",J8+21) | O8: local contribution after swaps. | Q8: regional\Tasks\00_implementation_greedy_search\README.md
A9: 8 | B9: 00 - Implementation, Greedy, Search | C9: B - Regional core | D9: Traffic Lights | E9: Submit | F9: Not started | G9: 00_implementation_greedy_search | H9: 2 | M9: =IF(J9="","",J9+7) | N9: =IF(J9="","",J9+21) | O9: ordered set + multiset bookkeeping. | Q9: regional\Tasks\00_implementation_greedy_search\README.md
A10: 9 | B10: 00 - Implementation, Greedy, Search | C10: B - Regional core | D10: Nested Ranges Count | E10: Submit | F10: Not started | G10: 00_implementation_greedy_search | M10: =IF(J10="","",J10+7) | N10: =IF(J10="","",J10+21) | O10: sorting ties + Fenwick/order statistic. | Q10: regional\Tasks\00_implementation_greedy_search\README.md
A11: 10 | B11: 00 - Implementation, Greedy, Search | C11: B - Regional core | D11: Sliding Window Cost | E11: Submit | F11: Not started | G11: 00_implementation_greedy_search | M11: =IF(J11="","",J11+7) | N11: =IF(J11="","",J11+21) | O11: median maintenance + careful accounting. | Q11: regional\Tasks\00_implementation_greedy_search\README.md
A12: 11 | B12: 00 - Implementation, Greedy, Search | C12: B - Regional core | D12: Meet in the Middle | E12: Submit | F12: Not started | G12: 00_implementation_greedy_search | H12: 2 | M12: =IF(J12="","",J12+7) | N12: =IF(J12="","",J12+21) | O12: split enumeration + sorting/two pointers. | N khoang 40 la tin hieu quan trong, bank cu chua co mau nay. | Q12: regional\Tasks\00_implementation_greedy_search\README.md
A13: 12 | B13: 00 - Implementation, Greedy, Search | C13: C - Advanced core | D13: Prefix Flip Hard Version | E13: Submit | F13: Not started | G13: 00_implementation_greedy_search | M13: =IF(J13="","",J13+7) | N13: =IF(J13="","",J13+21) | O13: lazy simulation of reverse/invert operations. | Q13: regional\Tasks\00_implementation_greedy_search\README.md
A14: 13 | B14: 00 - Implementation, Greedy, Search | C14: D - Regional scoring pipeline | D14: ICPC 2025 Regional - KayTee vs. TeaOne | E14: Submit | F14: Not started | G14: 00_implementation_greedy_search | M14: =IF(J14="","",J14+7) | N14: =IF(J14="","",J14+21) | O14: statement-to-code, validation and casework. | Q14: regional\Tasks\00_implementation_greedy_search\README.md
A15: 14 | B15: 00 - Implementation, Greedy, Search | C15: D - Regional scoring pipeline | D15: ICPC 2025 Regional - Aquatic Elevator | E15: Submit | F15: Not started | G15: 00_implementation_greedy_search | M15: =IF(J15="","",J15+7) | N15: =IF(J15="","",J15+21) | O15: adhoc optimization, identify the monotone/partition structure before coding. | Q15: regional\Tasks\00_implementation_greedy_search\README.md
A16: 15 | B16: 00 - Implementation, Greedy, Search | C16: D - Regional scoring pipeline | D16: ICPC 2025 Regional - Electronic Toll Collection | E16: Submit | F16: Not started | G16: 00_implementation_greedy_search | M16: =IF(J16="","",J16+7) | N16: =IF(J16="","",J16+21) | O16: adhoc graph observation; do not force a heavy template too early. | Q16: regional\Tasks\00_implementation_greedy_search\README.md
A17: 16 | B17: 00 - Implementation, Greedy, Search | C17: D - Regional scoring pipeline | D17: ICPC 2025 Regional - Divisibility Grid | E17: Submit | F17: Reference | G17: 08_proof_constructive_game | M17: =IF(J17="","",J17+7) | N17: =IF(J17="","",J17+21) | O17: constructive pattern + optimality proof. Day van la bai scoring; cho phep dung brute nho de tim pattern. | Q17: regional\Tasks\00_implementation_greedy_search\README.md
A18: 17 | B18: 00 - Implementation, Greedy, Search | C18: E - Stretch pipeline | D18: Robots | E18: Submit | F18: Not started | G18: 00_implementation_greedy_search | M18: =IF(J18="","",J18+7) | N18: =IF(J18="","",J18+21) | O18: greedy feasibility + binary search. | OI-level nhung transferable; lam full constraints va stress predicate. | Q18: regional\Tasks\00_implementation_greedy_search\README.md
A19: 18 | B19: 01 - Graph and Modeling | C19: A - Foundation | D19: Flight Discount | E19: Submit | F19: Not started | G19: 01_graph_modeling | H19: 3 | M19: =IF(J19="","",J19+7) | N19: =IF(J19="","",J19+21) | O19: Dijkstra with state / edge split. | Shortest path co mot thao tac dac biet. | Q19: regional\Tasks\01_graph_modeling\README.md
A20: 19 | B20: 01 - Graph and Modeling | C20: A - Foundation | D20: Investigation | E20: Submit | F20: Not started | G20: 01_graph_modeling | H20: 3 | M20: =IF(J20="","",J20+7) | N20: =IF(J20="","",J20+21) | O20: Dijkstra + count/min/max edges. | Re-laxation co nhieu thong tin, de sai tie. | Q20: regional\Tasks\01_graph_modeling\README.md
A21: 20 | B21: 01 - Graph and Modeling | C21: A - Foundation | D21: Coin Collector | E21: Submit | F21: Not started | G21: 01_graph_modeling | H21: 3 | M21: =IF(J21="","",J21+7) | N21: =IF(J21="","",J21+21) | O21: SCC condensation + DAG DP. | Mau Regional rat hay gap: compress truoc, DP sau. | Q21: regional\Tasks\01_graph_modeling\README.md
A22: 21 | B22: 01 - Graph and Modeling | C22: A - Foundation | D22: Giant Pizza | E22: Submit | F22: Not started | G22: 01_graph_modeling | H22: 8 | M22: =IF(J22="","",J22+7) | N22: =IF(J22="","",J22+21) | O22: 2-SAT, implication graph, SCC. | Bat buoc biet khi gap rang buoc either/or. | Q22: regional\Tasks\01_graph_modeling\README.md
A23: 22 | B23: 01 - Graph and Modeling | C23: A - Foundation | D23: Road Reparation | E23: Submit | F23: Not started | G23: 01_graph_modeling | H23: 3 | M23: =IF(J23="","",J23+7) | N23: =IF(J23="","",J23+21) | O23: Kruskal + DSU, MST cut property. | MST la lo hong lon cua bank cu. | Q23: regional\Tasks\01_graph_modeling\README.md
A24: 23 | B24: 01 - Graph and Modeling | C24: A - Foundation | D24: Necessary Roads | E24: Submit | F24: Not started | G24: 01_graph_modeling | H24: 3 | M24: =IF(J24="","",J24+7) | N24: =IF(J24="","",J24+21) | O24: bridges / low-link. | Primitive bat buoc truoc block-cut tree. | Q24: regional\Tasks\01_graph_modeling\README.md
A25: 24 | B25: 01 - Graph and Modeling | C25: A - Foundation | D25: Necessary Cities | E25: Submit | F25: Not started | G25: 01_graph_modeling | H25: 3 | M25: =IF(J25="","",J25+7) | N25: =IF(J25="","",J25+21) | O25: articulation points / low-link. | Root case va low-link condition rat de sai. | Q25: regional\Tasks\01_graph_modeling\README.md
A26: 25 | B26: 01 - Graph and Modeling | C26: B - Regional core | D26: Download Speed | E26: Submit | F26: Not started | G26: 01_graph_modeling | H26: 8 | M26: =IF(J26="","",J26+7) | N26: =IF(J26="","",J26+21) | O26: Dinic max flow. | Flow template baseline. | Q26: regional\Tasks\01_graph_modeling\README.md
A27: 26 | B27: 01 - Graph and Modeling | C27: B - Regional core | D27: Police Chase | E27: Submit | F27: Not started | G27: 01_graph_modeling | H27: 8 | M27: =IF(J27="","",J27+7) | N27: =IF(J27="","",J27+21) | O27: Max flow + min cut extraction. | Khong chi tinh maxflow, con phai reconstruct cut. | Q27: regional\Tasks\01_graph_modeling\README.md
A28: 27 | B28: 01 - Graph and Modeling | C28: B - Regional core | D28: School Dance | E28: Submit | F28: Not started | G28: 01_graph_modeling | H28: 8 | M28: =IF(J28="","",J28+7) | N28: =IF(J28="","",J28+21) | O28: Bipartite matching / max flow. | Assignment modeling co ban. | Q28: regional\Tasks\01_graph_modeling\README.md
A29: 28 | B29: 01 - Graph and Modeling | C29: B - Regional core | D29: Distinct Routes | E29: Submit | F29: Not started | G29: 01_graph_modeling | H29: 8 | M29: =IF(J29="","",J29+7) | N29: =IF(J29="","",J29+21) | O29: Max flow + path decomposition. | Code nang hon plain maxflow. | Q29: regional\Tasks\01_graph_modeling\README.md
A30: 29 | B30: 01 - Graph and Modeling | C30: B - Regional core | D30: Mail Delivery | E30: Submit | F30: Not started | G30: 01_graph_modeling | M30: =IF(J30="","",J30+7) | N30: =IF(J30="","",J30+21) | O30: Euler cycle. | Constructive graph output. | Q30: regional\Tasks\01_graph_modeling\README.md
A31: 30 | B31: 01 - Graph and Modeling | C31: B - Regional core | D31: Teleporters Path | E31: Submit | F31: Not started | G31: 01_graph_modeling | H31: 14 | M31: =IF(J31="","",J31+7) | N31: =IF(J31="","",J31+21) | O31: Directed Euler path. | Dieu kien dau/cuoi va output de sai. | Q31: regional\Tasks\01_graph_modeling\README.md
A32: 31 | B32: 01 - Graph and Modeling | C32: B - Regional core | D32: Planets Queries II | E32: Submit | F32: Not started | G32: 01_graph_modeling | H32: 14 | M32: =IF(J32="","",J32+7) | N32: =IF(J32="","",J32+21) | O32: functional graph, cycle/tree decomposition, binary lifting. | Functional graph xuat hien duoi nhieu lop statement. | Q32: regional\Tasks\01_graph_modeling\README.md
A33: 32 | B33: 01 - Graph and Modeling | C33: C - Advanced core | D33: Legacy | E33: Submit | F33: Not started | G33: 01_graph_modeling | M33: =IF(J33="","",J33+7) | N33: =IF(J33="","",J33+21) | O33: Segment-tree graph + Dijkstra. | Modeling nang, code dai, van trong scope Regional. | Q33: regional\Tasks\01_graph_modeling\README.md
A34: 33 | B34: 01 - Graph and Modeling | C34: C - Advanced core | D34: Delivery Bears | E34: Submit | F34: Not started | G34: 01_graph_modeling | M34: =IF(J34="","",J34+7) | N34: =IF(J34="","",J34+21) | O34: Max flow + binary search answer. | Flow predicate + toi uu dap an. | Q34: regional\Tasks\01_graph_modeling\README.md
A35: 34 | B35: 01 - Graph and Modeling | C35: C - Advanced core | D35: Task Assignment | E35: Submit | F35: Not started | G35: 01_graph_modeling | M35: =IF(J35="","",J35+7) | N35: =IF(J35="","",J35+21) | O35: min-cost flow / Hungarian. | Bai owner de hoan thien assignment modeling; mot trong hai cach la du. | Q35: regional\Tasks\01_graph_modeling\README.md
A36: 35 | B36: 01 - Graph and Modeling | C36: C - Advanced core | D36: Tourists | E36: Submit | F36: Not started | G36: 01_graph_modeling | M36: =IF(J36="","",J36+7) | N36: =IF(J36="","",J36+21) | O36: vertex-biconnected components + block-cut tree + data structure. | Block-cut tree can mot bai owner that; khong phai gate ca doi. | Q36: regional\Tasks\01_graph_modeling\README.md
A37: 36 | B37: 01 - Graph and Modeling | C37: C - Advanced core | D37: Reachable Nodes | E37: Submit | F37: Not started | G37: 01_graph_modeling | M37: =IF(J37="","",J37+7) | N37: =IF(J37="","",J37+21) | O37: topological DP + dynamic bitset. | Them bitset optimization tren DAG ma khong day no thanh topic rieng. | Q37: regional\Tasks\01_graph_modeling\README.md
A38: 37 | B38: 01 - Graph and Modeling | C38: D - Regional pipeline | D38: ICPC 2025 Regional - Matrix Multiplication | E38: Submit | F38: Not started | G38: 01_graph_modeling | H38: 14 | M38: =IF(J38="","",J38+7) | N38: =IF(J38="","",J38+21) | O38: graph modeling tu statement la. | Q38: regional\Tasks\01_graph_modeling\README.md
A39: 38 | B39: 01 - Graph and Modeling | C39: D - Regional pipeline | D39: Commuter Pass | E39: Submit | F39: Not started | G39: 01_graph_modeling | M39: =IF(J39="","",J39+7) | N39: =IF(J39="","",J39+21) | O39: shortest paths + structure of shortest path DAG. | Q39: regional\Tasks\01_graph_modeling\README.md
A40: 39 | B40: 01 - Graph and Modeling | C40: D - Regional pipeline | D40: One-Way Streets | E40: Submit | F40: Not started | G40: 01_graph_modeling | H40: 14 | M40: =IF(J40="","",J40+7) | N40: =IF(J40="","",J40+21) | O40: bridges, components, edge orientation. | Q40: regional\Tasks\01_graph_modeling\README.md
...

Sheet Topic Gates
A1: Topic | B1: Priority | C1: Deadline | D1: Regional core | E1: Advanced / Owner | F1: Coverage gate | G1: Gate status | H1: AC / Tasks | I1: Progress | J1: Notes
A2: 00 - Implementation, Greedy, Search | B2: P0 | C2: 46273 | D2: Sorting, prefix, two pointers, greedy, binary search, simulation | E2: MITM, local contribution, casework | F2: 3 easy tasks inside 90 minutes; no overflow/reset/indexing error | G2: Not started | H2: =COUNTIFS('Task Bank'!$B:$B,A2,'Task Bank'!$F:$F,"AC")&" / "&COUNTIFS('Task Bank'!$B:$B,A2,'Task Bank'!$F:$F,"<>Reference") -> 0 / 16 | I2: =IFERROR(COUNTIFS('Task Bank'!$B:$B,A2,'Task Bank'!$F:$F,"AC")/COUNTIFS('Task Bank'!$B:$B,A2,'Task Bank'!$F:$F,"<>Reference"),0) -> 0
A3: 01 - Graph and Modeling | B3: P0/P1 | C3: 20/09/2026 | D3: Shortest path, SCC, low-link, MST, 2-SAT, flow/matching | E3: Block-cut tree, functional graph, bitset DAG, min-cost flow | F3: Dijkstra/SCC/low-link/Dinic from scratch; one modeling pipeline AC | G3: Not started | H3: =COUNTIFS('Task Bank'!$B:$B,A3,'Task Bank'!$F:$F,"AC")&" / "&COUNTIFS('Task Bank'!$B:$B,A3,'Task Bank'!$F:$F,"<>Reference") -> 0 / 24 | I3: =IFERROR(COUNTIFS('Task Bank'!$B:$B,A3,'Task Bank'!$F:$F,"AC")/COUNTIFS('Task Bank'!$B:$B,A3,'Task Bank'!$F:$F,"<>Reference"),0) -> 0
A4: 02 - Data Structures | B4: P0/P2 | C4: 20/09/2026 | D4: Fenwick, lazy segment tree, sparse table, order statistic | E4: Persistent, Beats, Mo, rollback/PBS | F4: Lazy assign/add from scratch; persistence AC; owner rollback/PBS | G4: Not started | H4: =COUNTIFS('Task Bank'!$B:$B,A4,'Task Bank'!$F:$F,"AC")&" / "&COUNTIFS('Task Bank'!$B:$B,A4,'Task Bank'!$F:$F,"<>Reference") -> 0 / 20 | I4: =IFERROR(COUNTIFS('Task Bank'!$B:$B,A4,'Task Bank'!$F:$F,"AC")/COUNTIFS('Task Bank'!$B:$B,A4,'Task Bank'!$F:$F,"<>Reference"),0) -> 0
A5: 03 - Tree | B5: P0/P1 | C5: 20/09/2026 | D5: LCA, Euler, rerooting, HLD, path difference | E5: DSU on tree, centroid, virtual tree | F5: LCA/Euler/HLD from scratch; reroot AC; one advanced owner | G5: Not started | H5: =COUNTIFS('Task Bank'!$B:$B,A5,'Task Bank'!$F:$F,"AC")&" / "&COUNTIFS('Task Bank'!$B:$B,A5,'Task Bank'!$F:$F,"<>Reference") -> 0 / 20 | I5: =IFERROR(COUNTIFS('Task Bank'!$B:$B,A5,'Task Bank'!$F:$F,"AC")/COUNTIFS('Task Bank'!$B:$B,A5,'Task Bank'!$F:$F,"<>Reference"),0) -> 0
A6: 04 - Advanced DP | B6: P0/P1 | C6: 20/09/2026 | D6: Interval, bitmask, digit, profile, tree DP | E6: CHT, D&C, Knuth, WQS | F6: One AC per core type; explain optimization conditions | G6: Not started | H6: =COUNTIFS('Task Bank'!$B:$B,A6,'Task Bank'!$F:$F,"AC")&" / "&COUNTIFS('Task Bank'!$B:$B,A6,'Task Bank'!$F:$F,"<>Reference") -> 0 / 21 | I6: =IFERROR(COUNTIFS('Task Bank'!$B:$B,A6,'Task Bank'!$F:$F,"AC")/COUNTIFS('Task Bank'!$B:$B,A6,'Task Bank'!$F:$F,"<>Reference"),0) -> 0
A7: 05 - Math and Counting | B7: P0/P2 | C7: 46214 | D7: Modular, CRT, combinatorics, sieve, inclusion-exclusion | E7: Mobius/phi, floor sum, NTT, Gaussian/XOR basis | F7: Formula derived and brute checked; one advanced owner | G7: Not started | H7: =COUNTIFS('Task Bank'!$B:$B,A7,'Task Bank'!$F:$F,"AC")&" / "&COUNTIFS('Task Bank'!$B:$B,A7,'Task Bank'!$F:$F,"<>Reference") -> 0 / 21 | I7: =IFERROR(COUNTIFS('Task Bank'!$B:$B,A7,'Task Bank'!$F:$F,"AC")/COUNTIFS('Task Bank'!$B:$B,A7,'Task Bank'!$F:$F,"<>Reference"),0) -> 0
A8: 06 - Strings | B8: P0/P1 | C8: 20/09/2026 | D8: KMP/Z/hash, trie/Aho, suffix array/LCP | E8: Suffix automaton, Manacher, automaton DP | F8: KMP/Z/hash from scratch; Aho AC; suffix-array AC | G8: Not started | H8: =COUNTIFS('Task Bank'!$B:$B,A8,'Task Bank'!$F:$F,"AC")&" / "&COUNTIFS('Task Bank'!$B:$B,A8,'Task Bank'!$F:$F,"<>Reference") -> 0 / 19 | I8: =IFERROR(COUNTIFS('Task Bank'!$B:$B,A8,'Task Bank'!$F:$F,"AC")/COUNTIFS('Task Bank'!$B:$B,A8,'Task Bank'!$F:$F,"<>Reference"),0) -> 0
A9: 07 - Geometry | B9: P1 | C9: 46214 | D9: Orientation, intersection, polygon, hull, sweep | E9: Calipers, circle, precision | F9: Integer primitives pass edge cases; hull + sweep AC | G9: Not started | H9: =COUNTIFS('Task Bank'!$B:$B,A9,'Task Bank'!$F:$F,"AC")&" / "&COUNTIFS('Task Bank'!$B:$B,A9,'Task Bank'!$F:$F,"<>Reference") -> 0 / 18 | I9: =IFERROR(COUNTIFS('Task Bank'!$B:$B,A9,'Task Bank'!$F:$F,"AC")/COUNTIFS('Task Bank'!$B:$B,A9,'Task Bank'!$F:$F,"<>Reference"),0) -> 0
A10: 08 - Proof, Constructive, Game | B10: P1 | C10: 46214 | D10: Exchange argument, invariant, necessary/sufficient | E10: SG, tree game, hard constructive | F10: Two written greedy proofs; brute-small-to-proof workflow | G10: Not started | H10: =COUNTIFS('Task Bank'!$B:$B,A10,'Task Bank'!$F:$F,"AC")&" / "&COUNTIFS('Task Bank'!$B:$B,A10,'Task Bank'!$F:$F,"<>Reference") -> 0 / 17 | I10: =IFERROR(COUNTIFS('Task Bank'!$B:$B,A10,'Task Bank'!$F:$F,"AC")/COUNTIFS('Task Bank'!$B:$B,A10,'Task Bank'!$F:$F,"<>Reference"),0) -> 0

Sheet Virtual Log
A1: Week | B1: Planned date | C1: Contest | D1: Level | E1: Open | F1: Status | G1: Solved | H1: Penalty | I1: First AC (min) | J1: WA | K1: Easy missed | L1: Main failure | M1: Upsolve due | N1: Retry due | O1: Notes
A2: 1 | B2: 46200 | C2: Southern 2023 | D2: Southern | E2: Open | F2: Planned | M2: =IF(B2="","",B2+3) -> 46203 | N2: =IF(B2="","",B2+7) -> 46207
A3: 2 | B3: 46207 | C3: Southern 2024 | D3: Southern | E3: Open | F3: Planned | M3: =IF(B3="","",B3+3) -> 46210 | N3: =IF(B3="","",B3+7) -> 46214
A4: 7 | B4: 46242 | C4: Southern 2025 | D4: Southern | E4: Open | F4: Planned | M4: =IF(B4="","",B4+3) -> 46245 | N4: =IF(B4="","",B4+7) -> 46249
A5: 8 | B5: 46249 | C5: National 2021 | D5: National | E5: Open | F5: Planned | M5: =IF(B5="","",B5+3) -> 46252 | N5: =IF(B5="","",B5+7) -> 46256
A6: 12 | B6: 46277 | C6: National 2022 | D6: National | E6: Open | F6: Planned | M6: =IF(B6="","",B6+3) -> 46280 | N6: =IF(B6="","",B6+7) -> 46284
A7: 13 | B7: 46284 | C7: National 2023 | D7: National | E7: Open | F7: Planned | M7: =IF(B7="","",B7+3) -> 46287 | N7: =IF(B7="","",B7+7) -> 46291
A8: 14 | B8: 46291 | C8: Southern 2023 replay | D8: Southern | E8: Open | F8: Planned | M8: =IF(B8="","",B8+3) -> 46294 | N8: =IF(B8="","",B8+7) -> 46298
A9: 15 | B9: 46298 | C9: Southern 2024 replay | D9: Southern | E9: Open | F9: Planned | M9: =IF(B9="","",B9+3) -> 46301 | N9: =IF(B9="","",B9+7) -> 46305
A10: 16 | B10: 46305 | C10: Southern 2025 replay | D10: Southern | E10: Open | F10: Planned | M10: =IF(B10="","",B10+3) -> 46308 | N10: =IF(B10="","",B10+7) -> 46312
A11: 17 | B11: 46312 | C11: OFFICIAL Southern | D11: Official | E11: Open | F11: Planned | M11: =IF(B11="","",B11+3) -> 46315 | N11: =IF(B11="","",B11+7) -> 46319
A12: 18 | B12: 46319 | C12: National 2022 replay | D12: National | E12: Open | F12: Planned | M12: =IF(B12="","",B12+3) -> 46322 | N12: =IF(B12="","",B12+7) -> 46326
A13: 19 | B13: 46326 | C13: National 2023 | D13: National | E13: Open | F13: Planned | M13: =IF(B13="","",B13+3) -> 46329 | N13: =IF(B13="","",B13+7) -> 46333
... A27: 35 | B27: 46438 | C27: APAC mixed/replay 2 | D27: APAC | E27: Open | F27: Planned | M27: =IF(B27="","",B27+3) -> 46441 | N27: =IF(B27="","",B27+7) -> 46445

Sheet Weekly Rhythm
A1: WEEKLY RHYTHM - EDIT TIMES TO MATCH YOUR CLASS SCHEDULE
A3: Mode | B3: Session | C3: Duration | D3: Content | E3: Required output | F3: When
A4: Regular 13h | B4: 1 - Team virtual | C4: 5h | D4: Full contest, one computer, no editorial | E4: Score + WA + first AC + missed easy | F4: Weekend
A5: Regular 13h | B5: 2 - Team upsolve | C5: 2.5h | D5: Reconstruct model and code failed medium tasks | E5: Upsolve note + retry date | F5: Next day
A6: Regular 13h | B6: 3 - Topic block A | C6: 2h | D6: Foundation/core tasks from weekly focus | E6: 2 AC or one deep failure note | F6: Weekday
A7: Regular 13h | B7: 4 - Topic block B | C7: 2h | D7: Core/owner task or code-heavy pipeline | E7: 1 AC / implementation checkpoint | F7: Weekday
A8: Regular 13h | B8: 5 - Template/retry | C8: 1.5h | D8: Stress template and retry +7/+21 | E8: Template passes brute | F8: Short weekday
A9: Peak 17-18h | B9: 1-2 - Team virtuals | C9: 10h | D9: Two full contest sets | E9: Compare solve order and bottlenecks | F9: Weekend + one evening
A10: Peak 17-18h | B10: 3 - Upsolve | C10: 3h | D10: Only scoring failures first | E10: Medium failures closed in 72h | F10: Next day
A11: Peak 17-18h | B11: 4-5 - Retry/template | C11: 4-5h | D11: No broad new tags | E11: Stable notebook and two code streams | F11: Weekdays
A12: Taper 8-10h | B12: 1 - Light replay | C12: 3h | D12: Easy/medium problems only | E12: Confidence and clean code | F12: Early week
A13: Taper 8-10h | B13: 2 - Template check | C13: 2h | D13: Compile/stress notebook | E13: No unverified template | F13: Early week
A14: Taper 8-10h | B14: 3 - Rest/logistics | C14: 3-5h | D14: Sleep, travel, contest setup | E14: Ready to compete | F14: Before event
A18: Rule | B18: Meaning
A19: Do not tick the whole bank | B19: Pass topic gates; select tasks from failures and owner roles.
A20: Failed problem | B20: Tag model / technique / implementation / proof / time management.
A21: Retry | B21: Retry after 7 days and 21 days without old notes/code.
A22: Template | B22: Only add after AC or stress against brute.
A23: Regional-ready | B23: 3 consecutive Regional virtuals with 5+ solves and no missed easy due to primitive gaps.

Sheet Sources
A1: SOURCES AND FILE MAP
A3: Name | B3: Type | C3: Location / URL | D3: Use
A4: CP Control Board | B4: Local | C4: CP\README.md | D4: Phases, milestones, weekly load
A5: Regional Tasks | B5: Local | C5: CP\regional\Tasks\README.md | D5: A/B/C/D/E pipeline and gates
A6: Mixed contests | B6: Local | C6: CP\Asia\99_mixed_contests_hard_tasks\README.md | D6: Southern/National/Regional/APAC sets
A7: OLP-ICPC Vietnam 2026 | B7: Official | C7: https://www.olp.vn/tin-t%E1%BB%A9c/olympic-icpc/th%C3%B4ng-b%C3%A1o | D7: Published 2026 event dates
A8: VNOI Judge | B8: Judge | C8: https://oj.vnoi.info/ | D8: Submit Vietnam ICPC sets
A9: APAC 2024 | B9: Official PDF | C9: https://fileserv.icpc.jp/championship2024/tasks.pdf | D9: Virtual problem set
A10: APAC 2025 | B10: Official PDF | C10: https://fileserv.icpc.jp/championship2025/problemset.pdf | D10: Virtual problem set
A11: APAC 2026 | B11: Official PDF | C11: https://apac.icpc.global/assets/championship/2026/problemset.pdf | D11: Virtual problem set

Sheet Lists
A1: Task Status | B1: Week Status | C1: Failure Tag | D1: Virtual Status
A2: Not started | B2: Not started | C2: Model | D2: Planned
A3: Learning | B3: In progress | C3: Technique | D3: Done
A4: Solving | B4: Done | C4: Implementation | D4: Upsolving
A5: AC | B5: Blocked | C5: Proof | D5: Skipped
A6: Retry | B6: Skipped | C6: Time management
A7: Skip | C7: Reading
A8: Reference
